main -> try
foo -> try
foo -> catch
Trace: CustomErrorA a
